## 1. 다음 코드의 실행 결과와 이유는?

```javascript
setTimeout(() => console.log("A"), 0);
const promise = Promise.resolve();
promise.then(() => console.log("B"));
console.log("C");
```

## 2. 다음 코드의 실행 결과와 이유는?

```javascript
setTimeout(() => console.log("A"), 100);
const promise = new Promise((resolve) => {
  setTimeout(() => resolve(), 200);
});
promise.then(() => console.log("B"));
console.log("C");
```

## 3. 다음을 실행하면 undefined가 5번 실행된다. 그 이유와 0 ~4를 출력하기 위한 방법은?

```javascript
const numbers = [0, 1, 2, 3, 4];

for (var i = 0; i < numbers.length; i++) {
  setTimeout(function () {
    console.log(`[${i}] number ${numbers[i]} turn!`);
  }, i * 1000);
}
```

## 4. new 연산자와 호출한 Promise의 콜백함수는 reject함수가 호출됐다면, 호출되더라도 실행되지 않는다 (o/x)

## 5. newCoffee 호출 후 1초 뒤 콘솔창 출력결과는?

```javascript
let newCoffee = new Promise(function (resolve) {
  resolve("아메리카노");
  setTimeout(() => resolve("에스프레소"), 200);
});
newCoffee.then(console.log);
```

## 6. 실행 결과와 그 이유에 대해 간단히 설명하시오

```javascript
function buy_asis(item, price, quantity) {
  console.log(item + " 상품을 " + quantity + "개 골라서 점원에게 주었습니다.");
  setTimeout(function () {
    console.log("계산이 필요합니다.");
    var total = price * quantity;
    return total;
  }, 1000);
}
```

## 7. 콘솔에 출력될 결과를 맞춰보세요.

```javascript
function temp() {
  return new Promise((resolve, reject) => {
    reject();
  });
}

let testPromise = temp();

testPromise
  .then(() => {
    console.log("1번 1");
  })
  .then(() => {
    console.log("2번");
  })
  .catch(() => {
    console.log("에러 catch");
  })
  .then(() => {
    console.log("3번");
  });
```

```javascript
function temp() {
  return new Promise((resolve, reject) => {
    reject();
  });
}

let testPromise = temp();

testPromise
  .then(
    () => {
      console.log("1번 1");
    },
    () => {
      console.log("1번 2");
    }
  )
  .then(() => {
    console.log("2번");
  })
  .catch(() => {
    console.log("에러 catch");
  })
  .then(() => {
    console.log("3번");
  });
```

## 8. 코드의 실행 결과를 맞춰보세요.

```javascript
const promise = new Promise((resolve, reject) => {
  console.log(1);
  resolve();
  console.log(2);
});
promise.then(() => {
  console.log(3);
});
console.log(4);
```

## 1번 정답

> C -> B -> A

코드의 실행 순서는 (일반 코드 > Promise > setTimeout)순 이므로 첫 번째 코드는 실행 순서에 따라
C -> B -> A가 출력된다.

## 2번 정답

> C -> A -> B

두 번째 코드는 Promise내부의 setTimeout이 상단에 있는 setTimeout보다 늦게 실행되므로

C -> A -> B순으로 출력된다. 만일 B의 setTimeout 시간이 A보다 작을 경우 A보다 B가 먼저 출력된다.

## 3번 정답

for 루프는 종료조건에 도달할 때까지 실행되기에, i는 i++ 된 상태(5)가 된다.

그 이후 setTimeout이 실행되면서 인덱스 5번째가 없어서 undefined가 출력된다.

setTimeout을 즉시 실행함수로 감싼다

var 대신 let을 사용한다.

## 4번 정답

> x

reject가 호출되도 실행된다. 다만 실행 이후 then, catch문이 있다면 catch문이 실행된다.

## 5번 정답

> 아메리카노

첫 번째 resolve 호출 이후 바로 then으로 넘어가기 때문에 두 번째 resolve는 적용되지 않는다.

## 6번 정답

> 고구마 상품을 5개 골라서 점원에게 주었습니다.

> undefined원을 지불하였습니다.

> 계산이 필요합니다.

setTimeout 함수를 호출하고 1초 뒤에 다음 구문이 실행되는 것이 아니라
호출한 직후 바로 다음 구문을 실행하기 때문.

따라서 setTimeout 함수 내 메시지 출력과 리턴 구문은 1초 뒤에 실행이 될 것이고

tot 변수에 아무 값도 받지 못한 상태로 지불 메시지가 먼저 출력되었다.

## 7번 정답

> 1번 2, 2번, 3번

> 에러 catch, 3번

resolve() : 실행 시 프로미스는 Fulfilled 상태, then을 통해 resolve() 처리 결과 data를 받는다.

reject() : 실행 시 프로미스는 Rejected 상태, catch를 통해 reject() 처리 결과 data(실패 결과)를 받는다.

catch : then, 비동기 처리에서 발생한 에러를 받는다.

then: Promise가 수행될 때 호출되는 Function, Promise가 거부될 때 호출되는 Function을 인자로 받는다.

then은 두 개의 콜백 함수를 인자로 받을 수 있다. 첫 번째 콜백 함수는 resolve()가 실행된 결과를 받고,

두 번째 콜백 함수는 reject()가 실행된 결과를 받는다.

reject()가 실행되고 catch()가 reject()의 결과를 받아 처리를 하면 이후 then()은 동작한다.

## 8번 정답

> 1,2,4,3

promise 내부 구조 안에서의 코드는 동기적으로 실행된다.

그리고 resolve를 통해 then으로 전달된 console.log는 비동기로 실행되기 때문에

일반 코드가 먼저 실행된다.

resolve가 아닌 reject로 변경한다면 1,2,4 가 출력된다.
